<?xml version="1.0" ?>
<sdf version="1.7">
  <model name="green_robot">
    <pose>0 0 0.2 0 0 0</pose>

    <link name="base_link">
      <inertial>
        <mass>1.0</mass>
        <inertia>
          <ixx>0.1</ixx> <iyy>0.1</iyy> <izz>0.1</izz>
        </inertia>
      </inertial>
      <collision name="base_collision">
        <geometry><box><size>0.4 0.4 0.2</size></box></geometry>
      </collision>
      <visual name="base_visual">
        <geometry><box><size>0.4 0.4 0.2</size></box></geometry>
        <material>
          <ambient>0 1 0 1</ambient>
          <diffuse>0 1 0 1</diffuse>
        </material>
      </visual>
    </link>

    <link name="front_left_wheel">
      <pose>0.15 0.22 -0.1 1.5707 0 0</pose> 
      <collision name="collision">
        <geometry><cylinder><radius>0.1</radius><length>0.05</length></cylinder></geometry>
      </collision>
      <visual name="visual">
        <geometry><cylinder><radius>0.1</radius><length>0.05</length></cylinder></geometry>
        <material><ambient>0.5 0.5 0.5 1</ambient><diffuse>0.5 0.5 0.5 1</diffuse></material>
      </visual>
    </link>

    <link name="front_right_wheel">
      <pose>0.15 -0.22 -0.1 1.5707 0 0</pose>
      <collision name="collision">
        <geometry><cylinder><radius>0.1</radius><length>0.05</length></cylinder></geometry>
      </collision>
      <visual name="visual">
        <geometry><cylinder><radius>0.1</radius><length>0.05</length></cylinder></geometry>
        <material><ambient>0.5 0.5 0.5 1</ambient><diffuse>0.5 0.5 0.5 1</diffuse></material>
      </visual>
    </link>

    <link name="rear_left_wheel">
      <pose>-0.15 0.22 -0.1 1.5707 0 0</pose> 
      <collision name="collision">
        <geometry><cylinder><radius>0.1</radius><length>0.05</length></cylinder></geometry>
      </collision>
      <visual name="visual">
        <geometry><cylinder><radius>0.1</radius><length>0.05</length></cylinder></geometry>
        <material><ambient>0.5 0.5 0.5 1</ambient><diffuse>0.5 0.5 0.5 1</diffuse></material>
      </visual>
    </link>

    <link name="rear_right_wheel">
      <pose>-0.15 -0.22 -0.1 1.5707 0 0</pose>
      <collision name="collision">
        <geometry><cylinder><radius>0.1</radius><length>0.05</length></cylinder></geometry>
      </collision>
      <visual name="visual">
        <geometry><cylinder><radius>0.1</radius><length>0.05</length></cylinder></geometry>
        <material><ambient>0.5 0.5 0.5 1</ambient><diffuse>0.5 0.5 0.5 1</diffuse></material>
      </visual>
    </link>

    <link name="lidar_link">
      <pose>0 0 0.15 0 0 0</pose>
      <visual name="visual">
        <geometry><sphere><radius>0.05</radius></sphere></geometry>
        <material><ambient>0.5 0.5 0.5 1</ambient><diffuse>0.5 0.5 0.5 1</diffuse></material>
      </visual>
      <sensor name="lidar" type="gpu_lidar">
        <update_rate>10</update_rate>
        <topic>/scan</topic>
        <lidar>
          <scan><horizontal><samples>180</samples><min_angle>-1.5708</min_angle><max_angle>1.5708</max_angle></horizontal></scan>
          <range><min>0.15</min><max>12.0</max></range>
        </lidar>
      </sensor>
    </link>

    <joint name="front_left_wheel_joint" type="revolute">
      <parent>base_link</parent><child>front_left_wheel</child>
      <axis><xyz>0 0 1</xyz></axis>
    </joint>

    <joint name="front_right_wheel_joint" type="revolute">
      <parent>base_link</parent><child>front_right_wheel</child>
      <axis><xyz>0 0 1</xyz></axis>
    </joint>

    <joint name="rear_left_wheel_joint" type="revolute">
      <parent>base_link</parent><child>rear_left_wheel</child>
      <axis><xyz>0 0 1</xyz></axis>
    </joint>

    <joint name="rear_right_wheel_joint" type="revolute">
      <parent>base_link</parent><child>rear_right_wheel</child>
      <axis><xyz>0 0 1</xyz></axis>
    </joint>

    <joint name="lidar_joint" type="fixed">
      <parent>base_link</parent><child>lidar_link</child>
    </joint>

    <plugin
      filename="gz-sim-diff-drive-system"
      name="gz::sim::systems::DiffDrive">
      <left_joint>front_left_wheel_joint</left_joint>
      <left_joint>rear_left_wheel_joint</left_joint>
      <right_joint>front_right_wheel_joint</right_joint>
      <right_joint>rear_right_wheel_joint</right_joint>
      <wheel_separation>0.44</wheel_separation>
      <wheel_radius>0.1</wheel_radius>
      <topic>/cmd_vel</topic>
      <odom_topic>/odom</odom_topic>
      <tf_topic>/tf</tf_topic>
      <frame_id>odom</frame_id>
      <child_frame_id>base_link</child_frame_id>
    </plugin>
  </model>
</sdf>
